File: data/SC001 XRR.csv
[Measurement conditions]
Sample identification,
Comment,
Anode material,Cu
K-Alpha1 wavelength,1.5405980
K-Alpha2 wavelength,1.5444260
Ratio K-Alpha2/K-Alpha1,0.500
Divergence slit,Fixed,0.05mm
Receiving slit,0.05
Monochromator used,YES
Generator voltage, 45
Tube current, 40
File date and time,02/Sep/2019 15:57
Unit cell,TiO2[001]
h k l, 0 0 2
Scan axis,2Theta-Omega
Scan range,0.10500,9.89500
Scan step size,0.0100000
Omega offset,0.0000
No. of points, 979
Scan type,CONTINUOUS
Phi,1.81
Psi,-0.14
Z,1.721
Time per step,0.880
[Scan points]
Angle,Intensity
0.11000,681932.0
0.12000,721573.0
0.13000,763954.0
0.14000,802414.0
0.15000,842234.0
0.16000,884010.0
0.17000,921045.0
0.18000,958617.0
0.19000,998201.0
0.20000,1036510.0
0.21000,1073514.0
0.22000,1107880.0
0.23000,1145205.0
0.24000,1179193.0
0.25000,1217436.0
0.26000,1251440.0
0.27000,1286291.0
0.28000,1317451.0
0.29000,1351132.0
0.30000,1383149.0
0.31000,1418275.0
0.32000,1447628.0
0.33000,1478780.0
0.34000,1507956.0
0.35000,1536697.0
0.36000,1566689.0
0.37000,1595998.0
0.38000,1621148.0
0.39000,1648434.0
0.40000,1672941.0
0.41000,1697721.0
0.42000,1715992.0
0.43000,1737473.0
0.44000,1754646.0
0.45000,1767818.0
0.46000,1782630.0
0.47000,1789710.0
0.48000,1794185.0
0.49000,1788255.0
0.50000,1769980.0
0.51000,1733098.0
0.52000,1662527.0
0.53000,1534406.0
0.54000,1325628.0
0.55000,1066974.0
0.56000,819043.0
0.57000,633858.0
0.58000,502681.0
0.59000,408083.0
0.60000,338798.0
0.61000,285082.0
0.62000,241778.0
0.63000,206959.0
0.64000,179416.0
0.65000,156099.0
0.66000,136190.0
0.67000,119520.0
0.68000,105943.0
0.69000,93581.0
0.70000,83469.0
0.71000,74221.0
0.72000,65965.0
0.73000,59195.0
0.74000,52741.0
0.75000,47714.0
0.76000,43279.0
0.77000,38960.0
0.78000,34883.0
0.79000,31650.0
0.80000,28735.0
0.81000,25818.0
0.82000,23751.0
0.83000,21474.0
0.84000,19486.0
0.85000,17816.0
0.86000,16283.0
0.87000,14772.0
0.88000,13397.0
0.89000,12406.0
0.90000,11464.0
0.91000,10690.0
0.92000,9728.0
0.93000,8847.0
0.94000,8471.0
0.95000,7881.0
0.96000,7477.0
0.97000,7001.0
0.98000,6629.0
0.99000,6233.0
1.00000,5898.0
1.01000,5559.0
1.02000,5177.0
1.03000,4998.0
1.04000,4895.0
1.05000,4661.0
1.06000,4686.0
1.07000,4549.0
1.08000,4276.0
1.09000,4149.0
1.10000,4214.0
1.11000,4073.0
1.12000,4076.0
1.13000,3862.0
1.14000,3811.0
1.15000,3908.0
1.16000,3923.0
1.17000,3952.0
1.18000,3793.0
1.19000,3968.0
1.20000,3868.0
1.21000,3718.0
1.22000,3874.0
1.23000,3786.0
1.24000,3773.0
1.25000,3677.0
1.26000,3849.0
1.27000,3826.0
1.28000,3794.0
1.29000,3778.0
1.30000,3646.0
1.31000,3832.0
1.32000,3759.0
1.33000,3749.0
1.34000,3667.0
1.35000,3691.0
1.36000,3750.0
1.37000,3646.0
1.38000,3615.0
1.39000,3642.0
1.40000,3630.0
1.41000,3524.0
1.42000,3581.0
1.43000,3613.0
1.44000,3459.0
1.45000,3521.0
1.46000,3334.0
1.47000,3535.0
1.48000,3392.0
1.49000,3433.0
1.50000,3208.0
1.51000,3274.0
1.52000,3253.0
1.53000,3251.0
1.54000,3166.0
1.55000,3109.0
1.56000,3247.0
1.57000,3057.0
1.58000,2972.0
1.59000,3040.0
1.60000,2868.0
1.61000,2808.0
1.62000,2823.0
1.63000,2835.0
1.64000,2746.0
1.65000,2728.0
1.66000,2571.0
1.67000,2591.0
1.68000,2494.0
1.69000,2514.0
1.70000,2340.0
1.71000,2363.0
1.72000,2297.0
1.73000,2253.0
1.74000,2279.0
1.75000,2107.0
1.76000,2085.0
1.77000,2060.0
1.78000,1935.0
1.79000,1852.0
1.80000,1812.0
1.81000,1758.0
1.82000,1758.0
1.83000,1702.0
1.84000,1627.0
1.85000,1675.0
1.86000,1554.0
1.87000,1491.0
1.88000,1472.0
1.89000,1431.0
1.90000,1352.0
1.91000,1248.0
1.92000,1189.0
1.93000,1254.0
1.94000,1128.0
1.95000,1074.0
1.96000,1049.0
1.97000,1049.0
1.98000,967.0
1.99000,924.0
2.00000,882.0
2.01000,816.0
2.02000,858.0
2.03000,747.0
2.04000,725.0
2.05000,674.0
2.06000,663.0
2.07000,628.0
2.08000,592.0
2.09000,647.0
2.10000,540.0
2.11000,519.0
2.12000,499.0
2.13000,496.0
2.14000,476.0
2.15000,405.0
2.16000,424.0
2.17000,392.0
2.18000,352.0
2.19000,365.0
2.20000,340.0
2.21000,299.0
2.22000,305.0
2.23000,285.0
2.24000,250.0
2.25000,264.0
2.26000,234.0
2.27000,211.0
2.28000,213.0
2.29000,238.0
2.30000,207.0
2.31000,189.0
2.32000,165.0
2.33000,186.0
2.34000,166.0
2.35000,174.0
2.36000,160.0
2.37000,153.0
2.38000,160.0
2.39000,130.0
2.40000,143.0
2.41000,139.0
2.42000,138.0
2.43000,129.0
2.44000,119.0
2.45000,132.0
2.46000,144.0
2.47000,121.0
2.48000,120.0
2.49000,127.0
2.50000,127.0
2.51000,120.0
2.52000,134.0
2.53000,128.0
2.54000,131.0
2.55000,116.0
2.56000,131.0
2.57000,137.0
2.58000,127.0
2.59000,154.0
2.60000,141.0
2.61000,150.0
2.62000,129.0
2.63000,148.0
2.64000,145.0
2.65000,160.0
2.66000,186.0
2.67000,168.0
2.68000,163.0
2.69000,173.0
2.70000,158.0
2.71000,166.0
2.72000,177.0
2.73000,171.0
2.74000,143.0
2.75000,175.0
2.76000,187.0
2.77000,173.0
2.78000,180.0
2.79000,178.0
2.80000,192.0
2.81000,170.0
2.82000,162.0
2.83000,193.0
2.84000,184.0
2.85000,174.0
2.86000,168.0
2.87000,180.0
2.88000,179.0
2.89000,157.0
2.90000,178.0
2.91000,179.0
2.92000,184.0
2.93000,183.0
2.94000,178.0
2.95000,153.0
2.96000,181.0
2.97000,155.0
2.98000,177.0
2.99000,172.0
3.00000,174.0
3.01000,168.0
3.02000,172.0
3.03000,193.0
3.04000,181.0
3.05000,164.0
3.06000,165.0
3.07000,194.0
3.08000,183.0
3.09000,174.0
3.10000,153.0
3.11000,133.0
3.12000,168.0
3.13000,156.0
3.14000,147.0
3.15000,158.0
3.16000,154.0
3.17000,153.0
3.18000,117.0
3.19000,140.0
3.20000,129.0
3.21000,119.0
3.22000,138.0
3.23000,127.0
3.24000,142.0
3.25000,126.0
3.26000,118.0
3.27000,139.0
3.28000,101.0
3.29000,119.0
3.30000,125.0
3.31000,109.0
3.32000,100.0
3.33000,117.0
3.34000,109.0
3.35000,102.0
3.36000,95.0
3.37000,102.0
3.38000,87.0
3.39000,82.0
3.40000,87.0
3.41000,76.0
3.42000,71.0
3.43000,71.0
3.44000,67.0
3.45000,61.0
3.46000,60.0
3.47000,60.0
3.48000,75.0
3.49000,51.0
3.50000,64.0
3.51000,58.0
3.52000,42.0
3.53000,62.0
3.54000,40.0
3.55000,49.0
3.56000,47.0
3.57000,39.0
3.58000,33.0
3.59000,39.0
3.60000,25.0
3.61000,28.0
3.62000,29.0
3.63000,29.0
3.64000,37.0
3.65000,30.0
3.66000,18.0
3.67000,30.0
3.68000,15.0
3.69000,28.0
3.70000,23.0
3.71000,32.0
3.72000,16.0
3.73000,17.0
3.74000,15.0
3.75000,22.0
3.76000,17.0
3.77000,23.0
3.78000,18.0
3.79000,16.0
3.80000,20.0
3.81000,18.0
3.82000,20.0
3.83000,21.0
3.84000,9.0
3.85000,14.0
3.86000,14.0
3.87000,16.0
3.88000,15.0
3.89000,26.0
3.90000,13.0
3.91000,12.0
3.92000,17.0
3.93000,13.0
3.94000,22.0
3.95000,13.0
3.96000,16.0
3.97000,19.0
3.98000,19.0
3.99000,19.0
4.00000,17.0
4.01000,27.0
4.02000,15.0
4.03000,24.0
4.04000,24.0
4.05000,15.0
4.06000,19.0
4.07000,20.0
4.08000,20.0
4.09000,21.0
4.10000,16.0
4.11000,25.0
4.12000,25.0
4.13000,24.0
4.14000,15.0
4.15000,24.0
4.16000,27.0
4.17000,32.0
4.18000,24.0
4.19000,20.0
4.20000,26.0
4.21000,26.0
4.22000,23.0
4.23000,27.0
4.24000,25.0
4.25000,27.0
4.26000,27.0
4.27000,24.0
4.28000,32.0
4.29000,28.0
4.30000,31.0
4.31000,23.0
4.32000,21.0
4.33000,30.0
4.34000,34.0
4.35000,25.0
4.36000,30.0
4.37000,35.0
4.38000,36.0
4.39000,31.0
4.40000,29.0
4.41000,28.0
4.42000,31.0
4.43000,27.0
4.44000,28.0
4.45000,33.0
4.46000,29.0
4.47000,30.0
4.48000,35.0
4.49000,25.0
4.50000,30.0
4.51000,25.0
4.52000,29.0
4.53000,28.0
4.54000,37.0
4.55000,17.0
4.56000,21.0
4.57000,30.0
4.58000,23.0
4.59000,25.0
4.60000,26.0
4.61000,24.0
4.62000,28.0
4.63000,21.0
4.64000,23.0
4.65000,29.0
4.66000,21.0
4.67000,21.0
4.68000,32.0
4.69000,24.0
4.70000,17.0
4.71000,21.0
4.72000,17.0
4.73000,22.0
4.74000,25.0
4.75000,27.0
4.76000,18.0
4.77000,19.0
4.78000,17.0
4.79000,21.0
4.80000,14.0
4.81000,18.0
4.82000,25.0
4.83000,14.0
4.84000,18.0
4.85000,11.0
4.86000,12.0
4.87000,17.0
4.88000,13.0
4.89000,10.0
4.90000,6.0
4.91000,11.0
4.92000,22.0
4.93000,15.0
4.94000,6.0
4.95000,8.0
4.96000,10.0
4.97000,10.0
4.98000,16.0
4.99000,10.0
5.00000,8.0
5.01000,9.0
5.02000,9.0
5.03000,12.0
5.04000,7.0
5.05000,7.0
5.06000,4.0
5.07000,13.0
5.08000,7.0
5.09000,7.0
5.10000,7.0
5.11000,6.0
5.12000,5.0
5.13000,8.0
5.14000,11.0
5.15000,9.0
5.16000,11.0
5.17000,5.0
5.18000,10.0
5.19000,8.0
5.20000,9.0
5.21000,5.0
5.22000,12.0
5.23000,9.0
5.24000,9.0
5.25000,6.0
5.26000,2.0
5.27000,0.0
5.28000,5.0
5.29000,7.0
5.30000,4.0
5.31000,2.0
5.32000,9.0
5.33000,7.0
5.34000,7.0
5.35000,10.0
5.36000,6.0
5.37000,6.0
5.38000,9.0
5.39000,6.0
5.40000,3.0
5.41000,9.0
5.42000,7.0
5.43000,6.0
5.44000,6.0
5.45000,8.0
5.46000,10.0
5.47000,5.0
5.48000,11.0
5.49000,8.0
5.50000,10.0
5.51000,8.0
5.52000,4.0
5.53000,3.0
5.54000,5.0
5.55000,8.0
5.56000,9.0
5.57000,6.0
5.58000,9.0
5.59000,5.0
5.60000,11.0
5.61000,4.0
5.62000,9.0
5.63000,9.0
5.64000,12.0
5.65000,7.0
5.66000,10.0
5.67000,13.0
5.68000,11.0
5.69000,9.0
5.70000,6.0
5.71000,4.0
5.72000,7.0
5.73000,10.0
5.74000,6.0
5.75000,3.0
5.76000,11.0
5.77000,6.0
5.78000,10.0
5.79000,12.0
5.80000,11.0
5.81000,4.0
5.82000,10.0
5.83000,9.0
5.84000,5.0
5.85000,8.0
5.86000,9.0
5.87000,6.0
5.88000,15.0
5.89000,10.0
5.90000,10.0
5.91000,5.0
5.92000,16.0
5.93000,4.0
5.94000,8.0
5.95000,6.0
5.96000,10.0
5.97000,4.0
5.98000,6.0
5.99000,4.0
6.00000,9.0
6.01000,3.0
6.02000,10.0
6.03000,2.0
6.04000,2.0
6.05000,8.0
6.06000,9.0
6.07000,4.0
6.08000,8.0
6.09000,4.0
6.10000,10.0
6.11000,8.0
6.12000,11.0
6.13000,1.0
6.14000,12.0
6.15000,10.0
6.16000,12.0
6.17000,3.0
6.18000,8.0
6.19000,12.0
6.20000,4.0
6.21000,9.0
6.22000,7.0
6.23000,2.0
6.24000,5.0
6.25000,5.0
6.26000,6.0
6.27000,4.0
6.28000,4.0
6.29000,7.0
6.30000,3.0
6.31000,5.0
6.32000,8.0
6.33000,9.0
6.34000,5.0
6.35000,5.0
6.36000,4.0
6.37000,8.0
6.38000,6.0
6.39000,2.0
6.40000,2.0
6.41000,7.0
6.42000,5.0
6.43000,9.0
6.44000,9.0
6.45000,5.0
6.46000,7.0
6.47000,1.0
6.48000,5.0
6.49000,4.0
6.50000,4.0
6.51000,8.0
6.52000,9.0
6.53000,8.0
6.54000,3.0
6.55000,5.0
6.56000,5.0
6.57000,5.0
6.58000,9.0
6.59000,5.0
6.60000,5.0
6.61000,6.0
6.62000,7.0
6.63000,6.0
6.64000,6.0
6.65000,3.0
6.66000,4.0
6.67000,5.0
6.68000,6.0
6.69000,4.0
6.70000,6.0
6.71000,6.0
6.72000,5.0
6.73000,9.0
6.74000,5.0
6.75000,6.0
6.76000,8.0
6.77000,1.0
6.78000,1.0
6.79000,6.0
6.80000,5.0
6.81000,1.0
6.82000,3.0
6.83000,5.0
6.84000,7.0
6.85000,7.0
6.86000,4.0
6.87000,4.0
6.88000,2.0
6.89000,9.0
6.90000,4.0
6.91000,7.0
6.92000,6.0
6.93000,4.0
6.94000,3.0
6.95000,2.0
6.96000,8.0
6.97000,5.0
6.98000,8.0
6.99000,6.0
7.00000,3.0
7.01000,3.0
7.02000,3.0
7.03000,6.0
7.04000,1.0
7.05000,6.0
7.06000,4.0
7.07000,8.0
7.08000,1.0
7.09000,2.0
7.10000,5.0
7.11000,4.0
7.12000,4.0
7.13000,4.0
7.14000,2.0
7.15000,5.0
7.16000,3.0
7.17000,13.0
7.18000,1.0
7.19000,4.0
7.20000,2.0
7.21000,2.0
7.22000,8.0
7.23000,3.0
7.24000,5.0
7.25000,5.0
7.26000,5.0
7.27000,2.0
7.28000,5.0
7.29000,6.0
7.30000,3.0
7.31000,5.0
7.32000,4.0
7.33000,7.0
7.34000,4.0
7.35000,2.0
7.36000,4.0
7.37000,2.0
7.38000,5.0
7.39000,7.0
7.40000,2.0
7.41000,5.0
7.42000,5.0
7.43000,3.0
7.44000,2.0
7.45000,3.0
7.46000,0.0
7.47000,3.0
7.48000,6.0
7.49000,8.0
7.50000,5.0
7.51000,5.0
7.52000,3.0
7.53000,4.0
7.54000,3.0
7.55000,8.0
7.56000,4.0
7.57000,5.0
7.58000,1.0
7.59000,5.0
7.60000,7.0
7.61000,3.0
7.62000,5.0
7.63000,4.0
7.64000,9.0
7.65000,3.0
7.66000,5.0
7.67000,4.0
7.68000,4.0
7.69000,3.0
7.70000,4.0
7.71000,4.0
7.72000,3.0
7.73000,7.0
7.74000,7.0
7.75000,1.0
7.76000,4.0
7.77000,6.0
7.78000,6.0
7.79000,3.0
7.80000,5.0
7.81000,2.0
7.82000,5.0
7.83000,4.0
7.84000,3.0
7.85000,1.0
7.86000,5.0
7.87000,5.0
7.88000,6.0
7.89000,4.0
7.90000,4.0
7.91000,4.0
7.92000,2.0
7.93000,2.0
7.94000,4.0
7.95000,4.0
7.96000,3.0
7.97000,4.0
7.98000,3.0
7.99000,3.0
8.00000,1.0
8.01000,8.0
8.02000,5.0
8.03000,6.0
8.04000,5.0
8.05000,1.0
8.06000,4.0
8.07000,1.0
8.08000,3.0
8.09000,3.0
8.10000,3.0
8.11000,1.0
8.12000,4.0
8.13000,4.0
8.14000,1.0
8.15000,3.0
8.16000,2.0
8.17000,4.0
8.18000,9.0
8.19000,1.0
8.20000,3.0
8.21000,5.0
8.22000,1.0
8.23000,3.0
8.24000,3.0
8.25000,0.0
8.26000,3.0
8.27000,2.0
8.28000,1.0
8.29000,2.0
8.30000,0.0
8.31000,2.0
8.32000,2.0
8.33000,2.0
8.34000,1.0
8.35000,6.0
8.36000,7.0
8.37000,4.0
8.38000,7.0
8.39000,2.0
8.40000,2.0
8.41000,3.0
8.42000,2.0
8.43000,1.0
8.44000,3.0
8.45000,3.0
8.46000,4.0
8.47000,1.0
8.48000,4.0
8.49000,3.0
8.50000,5.0
8.51000,2.0
8.52000,4.0
8.53000,2.0
8.54000,4.0
8.55000,4.0
8.56000,1.0
8.57000,4.0
8.58000,5.0
8.59000,5.0
8.60000,4.0
8.61000,3.0
8.62000,2.0
8.63000,3.0
8.64000,2.0
8.65000,2.0
8.66000,2.0
8.67000,3.0
8.68000,2.0
8.69000,3.0
8.70000,2.0
8.71000,5.0
8.72000,3.0
8.73000,5.0
8.74000,1.0
8.75000,4.0
8.76000,7.0
8.77000,2.0
8.78000,8.0
8.79000,3.0
8.80000,1.0
8.81000,0.0
8.82000,2.0
8.83000,3.0
8.84000,5.0
8.85000,0.0
8.86000,4.0
8.87000,2.0
8.88000,1.0
8.89000,2.0
8.90000,4.0
8.91000,3.0
8.92000,1.0
8.93000,1.0
8.94000,4.0
8.95000,4.0
8.96000,3.0
8.97000,3.0
8.98000,2.0
8.99000,2.0
9.00000,1.0
9.01000,1.0
9.02000,2.0
9.03000,2.0
9.04000,3.0
9.05000,2.0
9.06000,3.0
9.07000,3.0
9.08000,2.0
9.09000,2.0
9.10000,3.0
9.11000,3.0
9.12000,5.0
9.13000,2.0
9.14000,1.0
9.15000,3.0
9.16000,1.0
9.17000,2.0
9.18000,0.0
9.19000,1.0
9.20000,4.0
9.21000,4.0
9.22000,3.0
9.23000,2.0
9.24000,2.0
9.25000,4.0
9.26000,4.0
9.27000,3.0
9.28000,1.0
9.29000,1.0
9.30000,4.0
9.31000,2.0
9.32000,2.0
9.33000,5.0
9.34000,2.0
9.35000,0.0
9.36000,1.0
9.37000,7.0
9.38000,5.0
9.39000,2.0
9.40000,2.0
9.41000,2.0
9.42000,6.0
9.43000,6.0
9.44000,2.0
9.45000,2.0
9.46000,5.0
9.47000,3.0
9.48000,2.0
9.49000,1.0
9.50000,1.0
9.51000,1.0
9.52000,2.0
9.53000,0.0
9.54000,4.0
9.55000,8.0
9.56000,3.0
9.57000,4.0
9.58000,2.0
9.59000,5.0
9.60000,5.0
9.61000,3.0
9.62000,1.0
9.63000,3.0
9.64000,2.0
9.65000,1.0
9.66000,3.0
9.67000,4.0
9.68000,4.0
9.69000,2.0
9.70000,2.0
9.71000,5.0
9.72000,2.0
9.73000,1.0
9.74000,4.0
9.75000,2.0
9.76000,1.0
9.77000,4.0
9.78000,4.0
9.79000,1.0
9.80000,2.0
9.81000,3.0
9.82000,0.0
9.83000,2.0
9.84000,3.0
9.85000,3.0
9.86000,1.0
9.87000,4.0
9.88000,3.0
9.89000,0.0