File: data/SC006 XRR.csv
[Measurement conditions]
Sample identification,
Comment,
Anode material,Cu
K-Alpha1 wavelength,1.5405980
K-Alpha2 wavelength,1.5444260
Ratio K-Alpha2/K-Alpha1,0.500
Divergence slit,Fixed,0.05mm
Receiving slit,0.05
Monochromator used,YES
Generator voltage, 45
Tube current, 40
File date and time,03/Sep/2019 14:46
Unit cell,
h k l, 0 0 0
Scan axis,2Theta-Omega
Scan range,0.20000,13.29000
Scan step size,0.0100000
Omega offset,0.0000
No. of points, 1309
Scan type,CONTINUOUS
Phi,0.00
Psi,0.00
Z,1.711
Time per step,0.440
[Scan points]
Angle,Intensity
0.20500,604602.0
0.21500,638083.0
0.22500,676212.0
0.23500,709647.0
0.24500,745274.0
0.25500,778370.0
0.26500,812718.0
0.27500,846710.0
0.28500,880836.0
0.29500,914872.0
0.30500,946512.0
0.31500,980258.0
0.32500,1013213.0
0.33500,1046076.0
0.34500,1080262.0
0.35500,1111769.0
0.36500,1143284.0
0.37500,1175444.0
0.38500,1205672.0
0.39500,1239319.0
0.40500,1268577.0
0.41500,1298604.0
0.42500,1325676.0
0.43500,1355783.0
0.44500,1384830.0
0.45500,1410661.0
0.46500,1437130.0
0.47500,1463478.0
0.48500,1484938.0
0.49500,1509482.0
0.50500,1533052.0
0.51500,1552187.0
0.52500,1569124.0
0.53500,1580262.0
0.54500,1595405.0
0.55500,1598837.0
0.56500,1597343.0
0.57500,1584026.0
0.58500,1554815.0
0.59500,1493201.0
0.60500,1389331.0
0.61500,1211794.0
0.62500,967839.0
0.63500,696664.0
0.64500,462906.0
0.65500,297008.0
0.66500,192926.0
0.67500,127294.0
0.68500,86882.0
0.69500,61299.0
0.70500,44268.0
0.71500,33829.0
0.72500,26725.0
0.73500,21656.0
0.74500,19263.0
0.75500,18006.0
0.76500,16946.0
0.77500,16761.0
0.78500,16906.0
0.79500,17176.0
0.80500,17801.0
0.81500,18735.0
0.82500,19343.0
0.83500,20256.0
0.84500,20803.0
0.85500,21362.0
0.86500,21580.0
0.87500,22255.0
0.88500,22570.0
0.89500,22879.0
0.90500,23027.0
0.91500,23219.0
0.92500,23298.0
0.93500,22979.0
0.94500,22987.0
0.95500,23063.0
0.96500,22712.0
0.97500,22320.0
0.98500,21913.0
0.99500,21232.0
1.00500,21029.0
1.01500,20709.0
1.02500,19845.0
1.03500,19538.0
1.04500,18598.0
1.05500,17993.0
1.06500,17633.0
1.07500,17062.0
1.08500,16265.0
1.09500,15807.0
1.10500,15073.0
1.11500,14591.0
1.12500,13958.0
1.13500,13258.0
1.14500,12339.0
1.15500,11891.0
1.16500,11464.0
1.17500,10614.0
1.18500,10039.0
1.19500,9410.0
1.20500,8987.0
1.21500,8510.0
1.22500,7874.0
1.23500,7313.0
1.24500,6868.0
1.25500,6238.0
1.26500,5790.0
1.27500,5257.0
1.28500,4920.0
1.29500,4397.0
1.30500,4112.0
1.31500,3873.0
1.32500,3539.0
1.33500,3125.0
1.34500,2878.0
1.35500,2639.0
1.36500,2354.0
1.37500,2181.0
1.38500,2056.0
1.39500,1775.0
1.40500,1628.0
1.41500,1439.0
1.42500,1332.0
1.43500,1168.0
1.44500,1104.0
1.45500,994.0
1.46500,922.0
1.47500,791.0
1.48500,786.0
1.49500,721.0
1.50500,686.0
1.51500,685.0
1.52500,620.0
1.53500,623.0
1.54500,603.0
1.55500,641.0
1.56500,665.0
1.57500,643.0
1.58500,679.0
1.59500,726.0
1.60500,740.0
1.61500,773.0
1.62500,789.0
1.63500,804.0
1.64500,914.0
1.65500,878.0
1.66500,960.0
1.67500,1006.0
1.68500,978.0
1.69500,1077.0
1.70500,1111.0
1.71500,1128.0
1.72500,1144.0
1.73500,1225.0
1.74500,1195.0
1.75500,1269.0
1.76500,1282.0
1.77500,1324.0
1.78500,1257.0
1.79500,1260.0
1.80500,1377.0
1.81500,1287.0
1.82500,1351.0
1.83500,1370.0
1.84500,1295.0
1.85500,1295.0
1.86500,1331.0
1.87500,1300.0
1.88500,1299.0
1.89500,1248.0
1.90500,1253.0
1.91500,1273.0
1.92500,1178.0
1.93500,1151.0
1.94500,1145.0
1.95500,1125.0
1.96500,1096.0
1.97500,1058.0
1.98500,1087.0
1.99500,1038.0
2.00500,977.0
2.01500,966.0
2.02500,932.0
2.03500,856.0
2.04500,882.0
2.05500,813.0
2.06500,722.0
2.07500,711.0
2.08500,681.0
2.09500,680.0
2.10500,674.0
2.11500,611.0
2.12500,528.0
2.13500,534.0
2.14500,486.0
2.15500,467.0
2.16500,452.0
2.17500,395.0
2.18500,388.0
2.19500,348.0
2.20500,321.0
2.21500,289.0
2.22500,294.0
2.23500,226.0
2.24500,225.0
2.25500,211.0
2.26500,207.0
2.27500,180.0
2.28500,194.0
2.29500,159.0
2.30500,172.0
2.31500,153.0
2.32500,135.0
2.33500,139.0
2.34500,109.0
2.35500,123.0
2.36500,117.0
2.37500,130.0
2.38500,116.0
2.39500,106.0
2.40500,121.0
2.41500,115.0
2.42500,124.0
2.43500,115.0
2.44500,130.0
2.45500,134.0
2.46500,145.0
2.47500,144.0
2.48500,149.0
2.49500,182.0
2.50500,188.0
2.51500,199.0
2.52500,181.0
2.53500,204.0
2.54500,237.0
2.55500,226.0
2.56500,216.0
2.57500,244.0
2.58500,261.0
2.59500,246.0
2.60500,263.0
2.61500,282.0
2.62500,246.0
2.63500,259.0
2.64500,272.0
2.65500,290.0
2.66500,287.0
2.67500,285.0
2.68500,271.0
2.69500,270.0
2.70500,290.0
2.71500,319.0
2.72500,308.0
2.73500,268.0
2.74500,297.0
2.75500,308.0
2.76500,283.0
2.77500,300.0
2.78500,317.0
2.79500,288.0
2.80500,279.0
2.81500,296.0
2.82500,258.0
2.83500,249.0
2.84500,259.0
2.85500,227.0
2.86500,245.0
2.87500,235.0
2.88500,244.0
2.89500,197.0
2.90500,233.0
2.91500,189.0
2.92500,175.0
2.93500,181.0
2.94500,164.0
2.95500,152.0
2.96500,156.0
2.97500,134.0
2.98500,132.0
2.99500,127.0
3.00500,111.0
3.01500,104.0
3.02500,113.0
3.03500,100.0
3.04500,112.0
3.05500,110.0
3.06500,99.0
3.07500,85.0
3.08500,68.0
3.09500,67.0
3.10500,67.0
3.11500,58.0
3.12500,46.0
3.13500,54.0
3.14500,46.0
3.15500,51.0
3.16500,37.0
3.17500,45.0
3.18500,38.0
3.19500,37.0
3.20500,25.0
3.21500,35.0
3.22500,24.0
3.23500,31.0
3.24500,28.0
3.25500,25.0
3.26500,24.0
3.27500,33.0
3.28500,30.0
3.29500,21.0
3.30500,43.0
3.31500,41.0
3.32500,36.0
3.33500,41.0
3.34500,45.0
3.35500,43.0
3.36500,46.0
3.37500,48.0
3.38500,38.0
3.39500,37.0
3.40500,41.0
3.41500,51.0
3.42500,57.0
3.43500,54.0
3.44500,55.0
3.45500,56.0
3.46500,57.0
3.47500,77.0
3.48500,51.0
3.49500,49.0
3.50500,56.0
3.51500,67.0
3.52500,81.0
3.53500,68.0
3.54500,83.0
3.55500,70.0
3.56500,80.0
3.57500,67.0
3.58500,78.0
3.59500,88.0
3.60500,67.0
3.61500,57.0
3.62500,74.0
3.63500,80.0
3.64500,69.0
3.65500,80.0
3.66500,85.0
3.67500,74.0
3.68500,67.0
3.69500,72.0
3.70500,66.0
3.71500,80.0
3.72500,82.0
3.73500,83.0
3.74500,65.0
3.75500,67.0
3.76500,70.0
3.77500,64.0
3.78500,61.0
3.79500,64.0
3.80500,50.0
3.81500,59.0
3.82500,48.0
3.83500,48.0
3.84500,46.0
3.85500,38.0
3.86500,43.0
3.87500,39.0
3.88500,45.0
3.89500,31.0
3.90500,23.0
3.91500,31.0
3.92500,32.0
3.93500,23.0
3.94500,23.0
3.95500,36.0
3.96500,32.0
3.97500,25.0
3.98500,24.0
3.99500,16.0
4.00500,22.0
4.01500,20.0
4.02500,20.0
4.03500,18.0
4.04500,16.0
4.05500,16.0
4.06500,14.0
4.07500,14.0
4.08500,14.0
4.09500,16.0
4.10500,13.0
4.11500,15.0
4.12500,18.0
4.13500,16.0
4.14500,18.0
4.15500,16.0
4.16500,15.0
4.17500,16.0
4.18500,13.0
4.19500,12.0
4.20500,17.0
4.21500,27.0
4.22500,24.0
4.23500,23.0
4.24500,24.0
4.25500,22.0
4.26500,21.0
4.27500,26.0
4.28500,21.0
4.29500,24.0
4.30500,17.0
4.31500,20.0
4.32500,43.0
4.33500,19.0
4.34500,25.0
4.35500,26.0
4.36500,21.0
4.37500,28.0
4.38500,21.0
4.39500,25.0
4.40500,23.0
4.41500,22.0
4.42500,26.0
4.43500,36.0
4.44500,31.0
4.45500,39.0
4.46500,28.0
4.47500,28.0
4.48500,34.0
4.49500,28.0
4.50500,33.0
4.51500,31.0
4.52500,31.0
4.53500,23.0
4.54500,22.0
4.55500,31.0
4.56500,30.0
4.57500,37.0
4.58500,28.0
4.59500,20.0
4.60500,21.0
4.61500,27.0
4.62500,16.0
4.63500,23.0
4.64500,28.0
4.65500,21.0
4.66500,26.0
4.67500,29.0
4.68500,16.0
4.69500,21.0
4.70500,15.0
4.71500,11.0
4.72500,20.0
4.73500,17.0
4.74500,16.0
4.75500,22.0
4.76500,21.0
4.77500,14.0
4.78500,12.0
4.79500,19.0
4.80500,13.0
4.81500,15.0
4.82500,19.0
4.83500,13.0
4.84500,12.0
4.85500,18.0
4.86500,16.0
4.87500,14.0
4.88500,15.0
4.89500,16.0
4.90500,8.0
4.91500,20.0
4.92500,9.0
4.93500,6.0
4.94500,10.0
4.95500,7.0
4.96500,12.0
4.97500,6.0
4.98500,8.0
4.99500,12.0
5.00500,7.0
5.01500,14.0
5.02500,13.0
5.03500,8.0
5.04500,6.0
5.05500,9.0
5.06500,6.0
5.07500,9.0
5.08500,11.0
5.09500,9.0
5.10500,16.0
5.11500,14.0
5.12500,15.0
5.13500,9.0
5.14500,18.0
5.15500,7.0
5.16500,11.0
5.17500,10.0
5.18500,12.0
5.19500,11.0
5.20500,14.0
5.21500,17.0
5.22500,13.0
5.23500,20.0
5.24500,12.0
5.25500,14.0
5.26500,20.0
5.27500,17.0
5.28500,8.0
5.29500,16.0
5.30500,22.0
5.31500,18.0
5.32500,14.0
5.33500,17.0
5.34500,13.0
5.35500,12.0
5.36500,16.0
5.37500,13.0
5.38500,25.0
5.39500,23.0
5.40500,15.0
5.41500,14.0
5.42500,22.0
5.43500,17.0
5.44500,18.0
5.45500,10.0
5.46500,14.0
5.47500,14.0
5.48500,18.0
5.49500,15.0
5.50500,6.0
5.51500,13.0
5.52500,7.0
5.53500,18.0
5.54500,11.0
5.55500,9.0
5.56500,8.0
5.57500,11.0
5.58500,19.0
5.59500,7.0
5.60500,13.0
5.61500,10.0
5.62500,10.0
5.63500,11.0
5.64500,13.0
5.65500,6.0
5.66500,16.0
5.67500,12.0
5.68500,7.0
5.69500,4.0
5.70500,8.0
5.71500,10.0
5.72500,11.0
5.73500,5.0
5.74500,6.0
5.75500,10.0
5.76500,6.0
5.77500,7.0
5.78500,9.0
5.79500,8.0
5.80500,13.0
5.81500,9.0
5.82500,11.0
5.83500,6.0
5.84500,7.0
5.85500,7.0
5.86500,13.0
5.87500,4.0
5.88500,12.0
5.89500,11.0
5.90500,6.0
5.91500,10.0
5.92500,6.0
5.93500,8.0
5.94500,7.0
5.95500,8.0
5.96500,6.0
5.97500,6.0
5.98500,13.0
5.99500,9.0
6.00500,6.0
6.01500,6.0
6.02500,11.0
6.03500,8.0
6.04500,10.0
6.05500,3.0
6.06500,5.0
6.07500,13.0
6.08500,9.0
6.09500,11.0
6.10500,6.0
6.11500,9.0
6.12500,9.0
6.13500,10.0
6.14500,6.0
6.15500,9.0
6.16500,16.0
6.17500,5.0
6.18500,11.0
6.19500,16.0
6.20500,9.0
6.21500,5.0
6.22500,8.0
6.23500,11.0
6.24500,5.0
6.25500,7.0
6.26500,7.0
6.27500,9.0
6.28500,12.0
6.29500,6.0
6.30500,9.0
6.31500,11.0
6.32500,7.0
6.33500,12.0
6.34500,12.0
6.35500,13.0
6.36500,4.0
6.37500,4.0
6.38500,6.0
6.39500,6.0
6.40500,13.0
6.41500,10.0
6.42500,6.0
6.43500,10.0
6.44500,11.0
6.45500,9.0
6.46500,10.0
6.47500,9.0
6.48500,11.0
6.49500,8.0
6.50500,7.0
6.51500,10.0
6.52500,13.0
6.53500,7.0
6.54500,6.0
6.55500,5.0
6.56500,7.0
6.57500,8.0
6.58500,7.0
6.59500,5.0
6.60500,6.0
6.61500,11.0
6.62500,6.0
6.63500,6.0
6.64500,4.0
6.65500,8.0
6.66500,3.0
6.67500,10.0
6.68500,5.0
6.69500,7.0
6.70500,4.0
6.71500,1.0
6.72500,7.0
6.73500,8.0
6.74500,7.0
6.75500,5.0
6.76500,9.0
6.77500,7.0
6.78500,10.0
6.79500,5.0
6.80500,5.0
6.81500,9.0
6.82500,6.0
6.83500,9.0
6.84500,10.0
6.85500,6.0
6.86500,10.0
6.87500,8.0
6.88500,9.0
6.89500,8.0
6.90500,9.0
6.91500,11.0
6.92500,7.0
6.93500,7.0
6.94500,15.0
6.95500,2.0
6.96500,3.0
6.97500,10.0
6.98500,12.0
6.99500,16.0
7.00500,6.0
7.01500,9.0
7.02500,4.0
7.03500,5.0
7.04500,6.0
7.05500,5.0
7.06500,6.0
7.07500,4.0
7.08500,10.0
7.09500,7.0
7.10500,5.0
7.11500,6.0
7.12500,3.0
7.13500,3.0
7.14500,8.0
7.15500,4.0
7.16500,7.0
7.17500,6.0
7.18500,8.0
7.19500,4.0
7.20500,6.0
7.21500,2.0
7.22500,5.0
7.23500,10.0
7.24500,5.0
7.25500,5.0
7.26500,7.0
7.27500,7.0
7.28500,4.0
7.29500,5.0
7.30500,3.0
7.31500,1.0
7.32500,9.0
7.33500,3.0
7.34500,4.0
7.35500,7.0
7.36500,7.0
7.37500,6.0
7.38500,5.0
7.39500,3.0
7.40500,5.0
7.41500,7.0
7.42500,5.0
7.43500,8.0
7.44500,7.0
7.45500,4.0
7.46500,4.0
7.47500,8.0
7.48500,5.0
7.49500,6.0
7.50500,6.0
7.51500,6.0
7.52500,10.0
7.53500,6.0
7.54500,6.0
7.55500,6.0
7.56500,7.0
7.57500,7.0
7.58500,11.0
7.59500,4.0
7.60500,2.0
7.61500,8.0
7.62500,5.0
7.63500,6.0
7.64500,9.0
7.65500,6.0
7.66500,5.0
7.67500,2.0
7.68500,2.0
7.69500,5.0
7.70500,7.0
7.71500,9.0
7.72500,2.0
7.73500,6.0
7.74500,4.0
7.75500,5.0
7.76500,3.0
7.77500,4.0
7.78500,1.0
7.79500,7.0
7.80500,10.0
7.81500,8.0
7.82500,4.0
7.83500,5.0
7.84500,4.0
7.85500,5.0
7.86500,6.0
7.87500,5.0
7.88500,4.0
7.89500,4.0
7.90500,5.0
7.91500,2.0
7.92500,7.0
7.93500,7.0
7.94500,5.0
7.95500,7.0
7.96500,4.0
7.97500,7.0
7.98500,3.0
7.99500,1.0
8.00500,6.0
8.01500,5.0
8.02500,7.0
8.03500,5.0
8.04500,4.0
8.05500,8.0
8.06500,8.0
8.07500,7.0
8.08500,1.0
8.09500,7.0
8.10500,7.0
8.11500,3.0
8.12500,3.0
8.13500,4.0
8.14500,5.0
8.15500,1.0
8.16500,6.0
8.17500,6.0
8.18500,6.0
8.19500,5.0
8.20500,2.0
8.21500,1.0
8.22500,3.0
8.23500,2.0
8.24500,5.0
8.25500,5.0
8.26500,2.0
8.27500,9.0
8.28500,7.0
8.29500,6.0
8.30500,3.0
8.31500,5.0
8.32500,7.0
8.33500,2.0
8.34500,7.0
8.35500,6.0
8.36500,10.0
8.37500,4.0
8.38500,4.0
8.39500,11.0
8.40500,5.0
8.41500,1.0
8.42500,5.0
8.43500,4.0
8.44500,7.0
8.45500,3.0
8.46500,2.0
8.47500,3.0
8.48500,8.0
8.49500,8.0
8.50500,3.0
8.51500,3.0
8.52500,2.0
8.53500,2.0
8.54500,4.0
8.55500,2.0
8.56500,4.0
8.57500,2.0
8.58500,4.0
8.59500,1.0
8.60500,3.0
8.61500,5.0
8.62500,6.0
8.63500,4.0
8.64500,3.0
8.65500,4.0
8.66500,4.0
8.67500,1.0
8.68500,4.0
8.69500,2.0
8.70500,5.0
8.71500,1.0
8.72500,5.0
8.73500,3.0
8.74500,5.0
8.75500,1.0
8.76500,4.0
8.77500,4.0
8.78500,5.0
8.79500,1.0
8.80500,4.0
8.81500,5.0
8.82500,3.0
8.83500,3.0
8.84500,2.0
8.85500,4.0
8.86500,5.0
8.87500,5.0
8.88500,5.0
8.89500,2.0
8.90500,3.0
8.91500,3.0
8.92500,5.0
8.93500,4.0
8.94500,3.0
8.95500,2.0
8.96500,5.0
8.97500,6.0
8.98500,2.0
8.99500,7.0
9.00500,4.0
9.01500,4.0
9.02500,2.0
9.03500,2.0
9.04500,3.0
9.05500,4.0
9.06500,5.0
9.07500,5.0
9.08500,6.0
9.09500,4.0
9.10500,4.0
9.11500,5.0
9.12500,5.0
9.13500,3.0
9.14500,3.0
9.15500,4.0
9.16500,2.0
9.17500,6.0
9.18500,2.0
9.19500,6.0
9.20500,4.0
9.21500,3.0
9.22500,2.0
9.23500,5.0
9.24500,8.0
9.25500,0.0
9.26500,3.0
9.27500,4.0
9.28500,2.0
9.29500,6.0
9.30500,2.0
9.31500,5.0
9.32500,6.0
9.33500,2.0
9.34500,2.0
9.35500,2.0
9.36500,1.0
9.37500,5.0
9.38500,4.0
9.39500,5.0
9.40500,8.0
9.41500,3.0
9.42500,4.0
9.43500,3.0
9.44500,2.0
9.45500,3.0
9.46500,3.0
9.47500,2.0
9.48500,5.0
9.49500,2.0
9.50500,3.0
9.51500,2.0
9.52500,4.0
9.53500,12.0
9.54500,2.0
9.55500,3.0
9.56500,6.0
9.57500,5.0
9.58500,2.0
9.59500,6.0
9.60500,2.0
9.61500,5.0
9.62500,8.0
9.63500,2.0
9.64500,3.0
9.65500,4.0
9.66500,7.0
9.67500,2.0
9.68500,4.0
9.69500,2.0
9.70500,8.0
9.71500,3.0
9.72500,2.0
9.73500,4.0
9.74500,2.0
9.75500,4.0
9.76500,2.0
9.77500,3.0
9.78500,4.0
9.79500,2.0
9.80500,3.0
9.81500,6.0
9.82500,4.0
9.83500,6.0
9.84500,2.0
9.85500,2.0
9.86500,1.0
9.87500,3.0
9.88500,4.0
9.89500,3.0
9.90500,6.0
9.91500,2.0
9.92500,4.0
9.93500,7.0
9.94500,3.0
9.95500,7.0
9.96500,5.0
9.97500,4.0
9.98500,7.0
9.99500,6.0
10.00500,2.0
10.01500,2.0
10.02500,4.0
10.03500,2.0
10.04500,8.0
10.05500,4.0
10.06500,3.0
10.07500,5.0
10.08500,3.0
10.09500,2.0
10.10500,4.0
10.11500,3.0
10.12500,1.0
10.13500,5.0
10.14500,3.0
10.15500,1.0
10.16500,2.0
10.17500,4.0
10.18500,1.0
10.19500,5.0
10.20500,7.0
10.21500,3.0
10.22500,1.0
10.23500,4.0
10.24500,4.0
10.25500,6.0
10.26500,3.0
10.27500,4.0
10.28500,9.0
10.29500,1.0
10.30500,3.0
10.31500,0.0
10.32500,2.0
10.33500,3.0
10.34500,5.0
10.35500,5.0
10.36500,2.0
10.37500,5.0
10.38500,3.0
10.39500,3.0
10.40500,5.0
10.41500,4.0
10.42500,3.0
10.43500,3.0
10.44500,3.0
10.45500,4.0
10.46500,3.0
10.47500,4.0
10.48500,4.0
10.49500,5.0
10.50500,4.0
10.51500,3.0
10.52500,4.0
10.53500,2.0
10.54500,5.0
10.55500,5.0
10.56500,7.0
10.57500,5.0
10.58500,1.0
10.59500,3.0
10.60500,5.0
10.61500,3.0
10.62500,1.0
10.63500,3.0
10.64500,4.0
10.65500,5.0
10.66500,2.0
10.67500,6.0
10.68500,3.0
10.69500,1.0
10.70500,2.0
10.71500,6.0
10.72500,3.0
10.73500,3.0
10.74500,1.0
10.75500,2.0
10.76500,0.0
10.77500,3.0
10.78500,3.0
10.79500,2.0
10.80500,6.0
10.81500,3.0
10.82500,4.0
10.83500,6.0
10.84500,5.0
10.85500,4.0
10.86500,1.0
10.87500,9.0
10.88500,5.0
10.89500,3.0
10.90500,2.0
10.91500,4.0
10.92500,4.0
10.93500,4.0
10.94500,3.0
10.95500,2.0
10.96500,1.0
10.97500,2.0
10.98500,3.0
10.99500,5.0
11.00500,6.0
11.01500,2.0
11.02500,1.0
11.03500,3.0
11.04500,3.0
11.05500,4.0
11.06500,3.0
11.07500,10.0
11.08500,0.0
11.09500,1.0
11.10500,7.0
11.11500,5.0
11.12500,6.0
11.13500,3.0
11.14500,3.0
11.15500,3.0
11.16500,0.0
11.17500,4.0
11.18500,5.0
11.19500,1.0
11.20500,4.0
11.21500,4.0
11.22500,3.0
11.23500,2.0
11.24500,2.0
11.25500,3.0
11.26500,2.0
11.27500,1.0
11.28500,0.0
11.29500,6.0
11.30500,5.0
11.31500,3.0
11.32500,3.0
11.33500,3.0
11.34500,2.0
11.35500,0.0
11.36500,4.0
11.37500,4.0
11.38500,1.0
11.39500,1.0
11.40500,1.0
11.41500,6.0
11.42500,4.0
11.43500,2.0
11.44500,2.0
11.45500,2.0
11.46500,3.0
11.47500,0.0
11.48500,1.0
11.49500,4.0
11.50500,1.0
11.51500,4.0
11.52500,3.0
11.53500,6.0
11.54500,1.0
11.55500,4.0
11.56500,1.0
11.57500,5.0
11.58500,5.0
11.59500,3.0
11.60500,3.0
11.61500,1.0
11.62500,1.0
11.63500,1.0
11.64500,3.0
11.65500,3.0
11.66500,4.0
11.67500,1.0
11.68500,2.0
11.69500,1.0
11.70500,4.0
11.71500,4.0
11.72500,1.0
11.73500,1.0
11.74500,5.0
11.75500,4.0
11.76500,4.0
11.77500,3.0
11.78500,4.0
11.79500,1.0
11.80500,2.0
11.81500,2.0
11.82500,2.0
11.83500,4.0
11.84500,1.0
11.85500,2.0
11.86500,3.0
11.87500,4.0
11.88500,2.0
11.89500,3.0
11.90500,4.0
11.91500,4.0
11.92500,7.0
11.93500,5.0
11.94500,3.0
11.95500,2.0
11.96500,4.0
11.97500,0.0
11.98500,3.0
11.99500,1.0
12.00500,5.0
12.01500,3.0
12.02500,3.0
12.03500,4.0
12.04500,2.0
12.05500,1.0
12.06500,0.0
12.07500,2.0
12.08500,5.0
12.09500,2.0
12.10500,4.0
12.11500,7.0
12.12500,3.0
12.13500,3.0
12.14500,1.0
12.15500,3.0
12.16500,4.0
12.17500,2.0
12.18500,5.0
12.19500,4.0
12.20500,5.0
12.21500,2.0
12.22500,5.0
12.23500,2.0
12.24500,2.0
12.25500,3.0
12.26500,6.0
12.27500,8.0
12.28500,1.0
12.29500,0.0
12.30500,4.0
12.31500,0.0
12.32500,0.0
12.33500,4.0
12.34500,3.0
12.35500,4.0
12.36500,2.0
12.37500,2.0
12.38500,3.0
12.39500,0.0
12.40500,6.0
12.41500,2.0
12.42500,4.0
12.43500,0.0
12.44500,0.0
12.45500,3.0
12.46500,6.0
12.47500,3.0
12.48500,3.0
12.49500,5.0
12.50500,2.0
12.51500,3.0
12.52500,4.0
12.53500,0.0
12.54500,3.0
12.55500,3.0
12.56500,4.0
12.57500,4.0
12.58500,2.0
12.59500,0.0
12.60500,3.0
12.61500,4.0
12.62500,5.0
12.63500,3.0
12.64500,2.0
12.65500,1.0
12.66500,2.0
12.67500,1.0
12.68500,5.0
12.69500,4.0
12.70500,1.0
12.71500,2.0
12.72500,2.0
12.73500,4.0
12.74500,2.0
12.75500,4.0
12.76500,2.0
12.77500,6.0
12.78500,1.0
12.79500,7.0
12.80500,1.0
12.81500,3.0
12.82500,9.0
12.83500,5.0
12.84500,2.0
12.85500,5.0
12.86500,1.0
12.87500,2.0
12.88500,1.0
12.89500,0.0
12.90500,2.0
12.91500,3.0
12.92500,4.0
12.93500,3.0
12.94500,1.0
12.95500,4.0
12.96500,0.0
12.97500,4.0
12.98500,1.0
12.99500,3.0
13.00500,3.0
13.01500,2.0
13.02500,3.0
13.03500,2.0
13.04500,1.0
13.05500,2.0
13.06500,4.0
13.07500,3.0
13.08500,4.0
13.09500,2.0
13.10500,1.0
13.11500,0.0
13.12500,2.0
13.13500,3.0
13.14500,4.0
13.15500,4.0
13.16500,5.0
13.17500,5.0
13.18500,1.0
13.19500,3.0
13.20500,4.0
13.21500,2.0
13.22500,2.0
13.23500,4.0
13.24500,5.0
13.25500,1.0
13.26500,4.0
13.27500,1.0
13.28500,0.0